Workbook

Sheet Vensim
A1: (01) adoption rate=
A2: ADOPTION SENSITIVITY *( performance effect on adoption) * affordability *
A3: ((POTENTIAL MARKET- Market Adoption)/ADOPTION TIME)
A4: Units: Customers/Year
A6: (02) ADOPTION SENSITIVITY=
A7: 1
A8: Units: Dmnl
A10: (03) ADOPTION TIME=
A11: 3
A12: Units: Year
A14: (04) affordability=
A15: 1/(1 + up front customers costs/COST NORM)
A16: Units: Dmnl
A17: 0–1 affordability index (higher is better)
A19: (05) AVERAGE LIFE=
A20: 8
A21: Units: Year
A23: (06) BASE COST=
A24: 500
A25: Units: Dollars/Units
A27: (07) BASE RAW MATERIAL PRICES=
A28: 100
A29: Units: Dollars/Tons
A30: Reference price
A32: (08) BASE UPFRONT=
A33: 200
A34: Units: Dollars/Units
A35: Baseline up-front customer cost
A37: (09) BASELINE VIRGIN DEMAND=
A38: 100
A39: Units: Tons/Year
A40: Reference demand
A42: (10) Capital Investment= INTEG (
A43: change in capital investment,
A44: INITIAL CAPITAL INVESTMENT)
A45: Units: Dollars/Year
A47: (11) CAPITAL NORM=
A48: 1000
A49: Units: Dollars/Year
A50: Scale for leasing availability
...

Sheet Interface
A1: PARAMETER | B1: COMMENT | C1: CD | D1: BAU | E1: UNITS
A2: (41) INITIAL TIME = 0 | B2: Simulation start | C2: 2025 | D2: 2000 | E2: Units: Year
A3: (84) TIME STEP = | B3: Euler dt (1/16 year) | C3: =D3 -> 0.0625 | D3: =Calibration!D3 -> 0.0625 | E3: Units: Year [0,?]
A4: (02) ADOPTION SENSITIVITY= | B4: Calibrates baseline speed of adoption | C4: =D4 -> 1.4366265 | D4: =Calibration!D4 -> 1.4366265 | E4: Units: Dmnl
A5: (03) ADOPTION TIME= | B5: Characteristic time to close the remaining market at baseline | C5: =D5 -> 7.4908095 | D5: =Calibration!D5 -> 7.4908095 | E5: Units: Year
A6: (05) AVERAGE LIFE= | B6: Average lifetime before retirement/replacement | C6: =D6 -> 0.89290336 | D6: =Calibration!D6 -> 0.89290336 | E6: Units: Year
A7: (06) BASE COST= | B7: Baseline unit cost | C7: =D7 -> 252.23051 | D7: =Calibration!D7 -> 252.23051 | E7: Units: Dollars/Units
A8: BASE COST MULTIPLER | C8: =D8 -> 0.2989792 | D8: =Calibration!D8 -> 0.2989792 | E8: Units: Dmnl
A9: (92) BASE PRICE= | B9: Baseline market selling price | C9: =D9 -> 455.83438 | D9: =Calibration!D9 -> 455.83438 | E9: Units: Dollars/Units
A10: (07) BASE RAW MATERIAL PRICES= | B10: Reference price | C10: =D10 -> 89.96988 | D10: =Calibration!D10 -> 89.96988 | E10: Units: Dollars/Tons
A11: (08) BASE UPFRONT= | B11: Baseline up-front customer cost | C11: =D11 -> 188.77296 | D11: =Calibration!D11 -> 188.77296 | E11: Units: Dollars/Units
A12: (09) BASELINE VIRGIN DEMAND= | B12: Reference demand | C12: =D12 -> 100.48156 | D12: =Calibration!D12 -> 100.48156 | E12: Units: Tons/Year
A13: (11) CAPITAL NORM= | B13: Scale for refillable packaging system availability | C13: =D13 -> 796.28499 | D13: =Calibration!D13 -> 796.28499 | E13: Units: Dollars/Year
A14: (17) CIRCULAR DESIGN DECAY RATE= | B14: Capability decay | C14: =Sensitivity!D3 -> 0.22512682 | D14: =Calibration!D14 -> 0.011256341 | E14: Units: 1/Year
A15: (18) CIRCULAR DESIGN GAIN= | B15: Build gain | C15: =Sensitivity!D2 -> 0.37703401 | D15: =Calibration!D15 -> 0.018851701 | E15: Units: 1/Year
A16: (19) COOP BASE= | B16: Baseline cooperation | C16: =D16 -> 0.1 | D16: =Calibration!D16 -> 0.1 | E16: Units: Dmnl
A17: (20) COOP TRUST SENS= | B17: Sensitivity of cooperation to trust | C17: =D17 -> 0.79985847 | D17: =Calibration!D17 -> 0.79985847 | E17: Units: Dmnl
A18: (22) COST NORM= | B18: Scaling for affordability | C18: =D18 -> 1057.762 | D18: =Calibration!D18 -> 1057.762 | E18: Units: Dollars/Units
A19: (24) DATA PER USER= | B19: Data production per customer | C19: =D19 -> 2.1013385 | D19: =Calibration!D19 -> 2.1013385 | E19: Units: Dmnl/(Customers*Year)
A20: (25) DEMAND PRICE ELASTICITY= | B20: Elasticity of price to demand | C20: =D20 -> 2.8641118 | D20: =Calibration!D20 -> 2.8641118 | E20: Units: Dmnl
A21: (26) DESIGN UPGRADE GAIN= | B21: Sensitivity of upgrades to data | C21: =D21 -> 0.00084294839 | D21: =Calibration!D21 -> 0.00084294839 | E21: Units: Dmnl
A22: (27) DESIGN UPGRADE REFERENCE= | B22: Reference scale for normalization | C22: =D22 -> 1.5713797 | D22: =Calibration!D22 -> 1.5713797 | E22: Units: Dmnl/Year
A23: (33) ECO EFFICIENCY BASE= | B23: Baseline eco-efficiency | C23: =D23 -> 0.1999041 | D23: =Calibration!D23 -> 0.1999041 | E23: Units: Dmnl
A24: (34) ECO EFFICIENCY SENSITIVITY= | B24: Contribution of recovery | C24: =D24 -> 0.80014282 | D24: =Calibration!D24 -> 0.80014282 | E24: Units: Dmnl
A25: (36) INITIAL CAPITAL INVESTMENT= | B25: Smoothed reinvestment from profits | C25: =D25 -> 0 | D25: =Calibration!D25 -> 0 | E25: Units: Dollars/Year
A26: (37) INITIAL CIRCULAR DESIGN= | B26: Capability index; influenced by upgrades and R&D | C26: =D26 -> 0.025 | D26: =Calibration!D26 -> 0.025 | E26: Units: Dmnl
A27: INITIAL CUMULATIVE CO2 EMISSIONS | C27: =D27 -> 0 | D27: =Calibration!D27 -> 0 | E27: Units: Tons CO2
A28: (38) INITIAL MARKET ADOPTION= | B28: Installed base of adopters (matches CLD term) | C28: =D28 -> 9.0624519 | D28: =Calibration!D28 -> 9.0624519 | E28: Units: Customers
A29: (39) INITIAL MATERIAL RECOVERY= | B29: 0–1 index of recovery effectiveness/capacity | C29: =D29 -> 0.005 | D29: =Calibration!D29 -> 0.005 | E29: Units: Dmnl
A30: (40) INITIAL PERFORMANCE= | B30: 0–1 index; increases with design upgrades | C30: =D30 -> 0.33952847 | D30: =Calibration!D30 -> 0.33952847 | E30: Units: Dmnl
A31: INITIAL RETAINED EARNINGS | C31: =D31 -> 0 | D31: =Calibration!D31 -> 0 | E31: Units: Dollars
A32: (43) INVEST DELAY= | B32: Adjustment delay | C32: =D32 -> 0.50073739 | D32: =Calibration!D32 -> 0.50073739 | E32: Units: Year
A33: (44) INVEST FRACTION= | B33: Share of profit invested | C33: =Sensitivity!D7 -> 0.02991982 | D33: =Calibration!D33 -> 0.001495991 | E33: Units: Dmnl
A34: (45) LEARNING RATE= | B34: Learning-by-doing strength | C34: =Sensitivity!D6 -> 1.5911561 | D34: =Calibration!D34 -> 0.079557807 | E34: Units: Dmnl
A35: MANUFACTURING COST CHANGE RATE | C35: =D35 -> 0.36121888 | D35: =Calibration!D35 -> 0.36121888 | E35: Units: 1/Year
A36: (52) MATERIAL COST SHARE= | B36: Share of raw material costs in unit cost | C36: =D36 -> 0.26967313 | D36: =Calibration!D36 -> 0.26967313 | E36: Units: Tons/Units
A37: MAXIMUM MAINTENANCE COST MULTIPLER | C37: =D37 -> 1.5281261 | D37: =Calibration!D37 -> 1.5281261 | E37: Units: Dmnl
A38: MINIMUM MAINTENANCE COST MULTIPLER | C38: =D38 -> 0.92486728 | D38: =Calibration!D38 -> 0.92486728 | E38: Units: Dmnl
A39: (57) PERFORMANCE DECAY RATE= | B39: Mean reversion/decay | C39: =D39 -> 0.015446432 | D39: =Calibration!D39 -> 0.015446432 | E39: Units: 1/Year
A40: (59) PERFORMANCE GAIN= | B40: Gain linking upgrades to performance | C40: =D40 -> 0.011951217 | D40: =Calibration!D40 -> 0.011951217 | E40: Units: Dmnl
...

Sheet Model_CI
A1: PARAMETER | B1: BAU | C1: CD | D1: UNITS | E1: Time | F1: (01) adoption rate= | G1: (04) affordability= | H1: (10) Capital Investment= INTEG ( | I1: (12) change in capital investment= | J1: (13) change in inter firm trust= | K1: (14) Circular Design= INTEG ( | L1: (15) circular design build= | M1: (16) circular design decay= | N1: (21) cooperation in logistics= | O1: (23) customer satisfaction= | P1: (28) design upgrades= | Q1: (29) design upgrades norm= | R1: (30) desired capital investment= | S1: (31) desired inter firm trust= | T1: (32) eco efficiency= | U1: (42) Inter Firm Trust= INTEG ( | V1: (46) refillable packaging adoption= | W1: (48) manufacturing costs= | X1: (49) Market Adoption= INTEG ( | Y1: (50) market adoption index= | Z1: (53) Material Recovery= INTEG ( | AA1: (54) Performance= INTEG ( | AB1: (55) performance data= | AC1: (56) performance decay= | AD1: (58) performance effect on adoption= | AE1: (60) performance improvement= | AF1: (63) pressure for systemic change= | AG1: (65) price= | AH1: price adjustment | AI1: maintenance cost adjustment | AJ1: maintenance cost factor | AK1: price outflow | AL1: (66) profit= | AM1: (69) R and D investment= | AN1: (73) r and d push= | AO1: (74) raw material cost addition= | AP1: (75) raw material prices= | AQ1: (77) recovery build= | AR1: (78) recovery decay= | AS1: (80) retirement rate= | AT1: (81) revenue= | AU1: (82) sales= | AV1: Cum Sales | AW1: (89) up front customers costs= | AX1: (90) virgin material demand= | AY1: Retained Earnings | AZ1: (95) total material demand= | BA1: (96) recovered material demand= | BB1: (97) CO2 emissions per year= | BC1: (98) cumulative CO2 emissions=
A2: (41) INITIAL TIME = 0 | B2: =Model_BAU!B2 -> 2000 | C2: 2025 | D2: Units: Year | E2: Units: Year | F2: Units: Customers/Year | G2: Units: Dmnl | H2: Units: Dollars/Year | I2: Units: Dollars/Year/Year | J2: Units: Dmnl/Year | K2: Units: Dmnl | L2: Units: Dmnl/Year | M2: Units: Dmnl/Year | N2: Units: Dmnl | O2: Units: Dmnl | P2: Units: Dmnl/Year | Q2: Units: Dmnl | R2: Units: Dollars/Year | S2: Units: Dmnl | T2: Units: Dmnl | U2: Units: Dmnl | V2: Units: Dmnl | W2: Units: Dollars/Units | X2: Units: Customers | Y2: Units: Dmnl | Z2: Units: Dmnl | AA2: Units: Dmnl | AB2: Units: Dmnl/Year | AC2: Units: Dmnl/Year | AD2: Units: Dmnl | AE2: Units: Dmnl/Year | AF2: Units: Dmnl | AG2: Units: Dollars/Units | AH2: Units: Dollars/Units/Year | AI2: Units: Dollars/Units/Year | AJ2: Units: Dollars/Units | AK2: Units: Dollars/Units/Year | AL2: Units: Dollars/Year | AM2: Units: Dollars/Year | AN2: Units: Dmnl | AO2: Units: Dollars/Units | AP2: Units: Dollars/Tons | AQ2: Units: Dmnl/Year | AR2: Units: Dmnl/Year | AS2: Units: Customers/Year | AT2: Units: Dollars/Year | AU2: Units: Units/Year | AV2: Units: Units | AW2: Units: Dollars/Units | AX2: Units: Tons/Year | AY2: Units: Dollars | AZ2: Units: Tons/Year | BA2: Units: Tons/Year | BB2: Units: Tons CO2/Year | BC2: Units: Tons CO2
A3: (84) TIME STEP = | B3: =Model_BAU!B3 -> 0.0625 | C3: =Interface!C3 -> 0.0625 | D3: Units: Year [0,?] | E3: =B2 -> 2000 | F3: =B$4*AD3*G3*(B$9/AG3)^B$20*((B$42-X3)/B$5) -> 221.66132 | G3: =1/(1 + AW3/B$18) -> 0.84856185 | H3: =B$25 -> 0 | I3: =(R3-H3)/B$32 -> 16704.423 | J3: =(S3-U3)/B$57 -> 0.11994559 | K3: =B$26 -> 0.025 | L3: =B$15 * (Q3 + AN3) * (1 - K3) -> 0.01855919 | M3: =K3*B$14 -> 0.00028140852 | N3: =B$16 + B$17*U3 -> 0.25997169 | O3: =AA3 -> 0.33952847 | P3: =B$21*AB3 -> 0.016052501 | Q3: =P3/(B$22+P3) -> 0.010112244 | R3: =MAX(0,AL3*B$33) -> 8364.5294 | S3: =B$56 + B$58 * MIN(1, MAX(0, AL3)/B$46) -> 0.79972799 | T3: =B$23+B$24*Z3 -> 0.20390482 | U3: =B$56 -> 0.2 | V3: =MIN(1, H3/(B$13 + H3)) -> 0 | W3: =MAX(B$8*$B$7, $B$7*(1 - $B$34*LN(1 + Y3))) + AO3 -> 269.58858 | X3: =B$28 -> 9.0624519 | Y3: =X3/B$28 -> 1 | Z3: =B$29 -> 0.005 | AA3: =B$30 -> 0.33952847 | AB3: =X3*B$19 -> 19.043279 | AC3: =AA3*B$39 -> 0.0052445035 | AD3: =MIN(1,AA3^B$41) -> 0.088724115 | AE3: =B$40*P3*(1-AA3) -> 0.00012670943 | AF3: =B$43*T3 -> 0.20170754 | AG3: =B9 -> 455.83438 | AH3: =AG3*B$44 -> 270.29722 | AI3: =B$35*MIN(B$37*B$9,MAX(B$38*B$9,AJ3)) -> 152.28493 | AJ3: =W3*B$20/(B$20-1) -> 414.20897 | AK3: =B$45*AG3 -> 539.9626 | AL3: =AT3-AU3*W3 -> 5591296.6 | AM3: =B$47+B$50*MAX(0, AL3 )+B$49 *AF3 -> 195619.7 | AN3: =AM3/(B$48+AM3) -> 0.99961452 | AO3: =B$36*AP3 -> 31.267388 | AP3: =$B$10*(1 + $B$51*LN(1 + AX3/$B$12)) -> 115.94551 | AQ3: =B$54*K3*(1-Z3) -> 0.00064513673 | AR3: =Z3*B$52 -> 7.6806669e-05 | AS3: =X3/B$6 -> 10.149421 | AT3: =AU3*AG3 -> 13684632 | AU3: =F3*B$59*O3 -> 30021.061 | AV3: =0 -> 0 | AW3: =B$11*(AG3/B$9)*(1 - B$55*MIN(1,V3)) -> 188.77296 | AX3: =AU3*B$61*(1-Z3) -> 29695.178 | AY3: =B31 -> 0 | AZ3: =AU3*B$61 -> 29844.4 | BA3: =AZ3*Z3 -> 149.222 | BB3: =AX3*B$60+BA3*B$53 -> 59496.859 | BC3: =B27 -> 0
A4: (02) ADOPTION SENSITIVITY= | B4: =Model_BAU!B4 -> 1.4366265 | C4: =Interface!C4 -> 1.4366265 | D4: Units: Dmnl | E4: =E3+B$3 -> 2000.0625 | F4: =B$4*AD4*G4*(B$9/AG4)^B$20*((B$42-X4)/B$5) -> 242.34454 | G4: =1/(1 + AW4/B$18) -> 0.8882536 | H4: =H3+B$3*I3 -> 1044.0265 | I4: =(R4-H4)/B$32 -> 16508.429 | J4: =(S4-U4)/B$57 -> 0.11844627 | K4: =K3+B$3*(L3-M3) -> 0.026142361 | L4: =B$15 * (Q4 + AN4) * (1 - K4) -> 0.018802337 | M4: =K4*B$14 -> 0.00029426733 | N4: =B$16 + B$17*U4 -> 0.26596791 | O4: =AA4 -> 0.33920861 | P4: =B$21*AB4 -> 0.039468454 | Q4: =P4/(B$22+P4) -> 0.02450166 | R4: =MAX(0,AL4*B$33) -> 9310.4143 | S4: =B$56 + B$58 * MIN(1, MAX(0, AL4)/B$46) -> 0.79972799 | T4: =MIN(1,B$23+B$24*Z4) -> 0.20393324 | U4: =U3+B$3*J3 -> 0.2074966 | V4: =MIN(1, H4/(B$13 + H4)) -> 0.56730966 | W4: =MAX(B$8*$B$7, $B$7*(1 - $B$34*LN(1 + Y4))) + AO4 -> 258.70519 | X4: =X3+B$3*(F3-AS3) -> 22.281946 | Y4: =X4/B$28 -> 2.4587105 | Z4: =Z3+B$3*(AQ3-AR3) -> 0.0050355206 | AA4: =AA3+B$3*(AE3-AC3) -> 0.33920861 | AB4: =X4*B$19 -> 46.82191 | AC4: =AA4*B$39 -> 0.0052395628 | AD4: =MIN(1,AA4^B$41) -> 0.088536795 | AE4: =B$40*P4*(1-AA4) -> 0.0003116927 | AF4: =B$43*T4 -> 0.20173566 | AG4: =AG3+(AH3+AI3-AK3)*B$3 -> 448.4981 | AH4: =AG4*B$44 -> 265.94701 | AI4: =B$35*MIN(B$37*B$9,MAX(B$38*B$9,AJ4)) -> 152.28493 | AJ4: =W4*B$20/(B$20-1) -> 397.4872 | AK4: =B$45*AG4 -> 531.27235 | AL4: =AT4-AU4*W4 -> 6223576.4 | AM4: =B$47+B$50*MAX(0, AL4 )+B$49 *AF4 -> 217739.67 | AN4: =AM4/(B$48+AM4) -> 0.99965366 | AO4: =B$36*AP4 -> 31.375618 | AP4: =$B$10*(1 + $B$51*LN(1 + AX4/$B$12)) -> 116.34685 | AQ4: =B$54*K4*(1-Z4) -> 0.00067459182 | AR4: =Z4*B$52 -> 7.7352314e-05 | AS4: =X4/B$6 -> 24.954488 | AT4: =AU4*AG4 -> 14706883 | AU4: =F4*B$59*O4 -> 32791.405 | AV4: =AV3+AU3*B$3 -> 1876.3163 | AW4: =B$11*(AG4/B$9)*(1 - B$55*MIN(1,V4)) -> 133.07134 | AX4: =AU4*B$61*(1-Z4) -> 32434.291 | AY4: =AY3+AL4*B$3 -> 388973.52 | AZ4: =AU4*B$61 -> 32598.442 | BA4: =AZ4*Z4 -> 164.15013 | BB4: =AX4*B$60+BA4*B$53 -> 64985.702 | BC4: =BC3+BB3*B$3 -> 3718.5537
A5: (03) ADOPTION TIME= | B5: =Model_BAU!B5 -> 7.4908095 | C5: =Interface!C5 -> 7.4908095 | D5: Units: Year | E5: =E4+B$3 -> 2000.125 | F5: =B$4*AD5*G5*(B$9/AG5)^B$20*((B$42-X5)/B$5) -> 256.38877 | G5: =1/(1 + AW5/B$18) -> 0.90057953 | H5: =H4+B$3*I4 -> 2075.8033 | I5: =(R5-H5)/B$32 -> 15517.207 | J5: =(S5-U5)/B$57 -> 0.11696569 | K5: =K4+B$3*(L4-M4) -> 0.027299116 | L5: =B$15 * (Q5 + AN5) * (1 - K5) -> 0.019043665 | M5: =K5*B$14 -> 0.00030728815 | N5: =B$16 + B$17*U5 -> 0.27188918 | O5: =AA5 -> 0.33890062 | P5: =B$21*AB5 -> 0.063535162 | Q5: =P5/(B$22+P5) -> 0.03886145 | R5: =MAX(0,AL5*B$33) -> 9845.8493 | S5: =B$56 + B$58 * MIN(1, MAX(0, AL5)/B$46) -> 0.79972799 | T5: =MIN(1,B$23+B$24*Z5) -> 0.2039631 | U5: =U4+B$3*J4 -> 0.21489949 | V5: =MIN(1, H5/(B$13 + H5)) -> 0.72275052 | W5: =MAX(B$8*$B$7, $B$7*(1 - $B$34*LN(1 + Y5))) + AO5 -> 251.54708 | X5: =X4+B$3*(F4-AS4) -> 35.868824 | Y5: =X5/B$28 -> 3.9579603 | Z5: =Z4+B$3*(AQ4-AR4) -> 0.0050728481 | AA5: =AA4+B$3*(AE4-AC4) -> 0.33890062 | AB5: =X5*B$19 -> 75.372541 | AC5: =AA5*B$39 -> 0.0052348054 | AD5: =MIN(1,AA5^B$41) -> 0.088356633 | AE5: =B$40*P5*(1-AA5) -> 0.00050198765 | AF5: =B$43*T5 -> 0.2017652 | AG5: =AG4+(AH4+AI4-AK4)*B$3 -> 441.43308 | AH5: =AG5*B$44 -> 261.75764 | AI5: =B$35*MIN(B$37*B$9,MAX(B$38*B$9,AJ5)) -> 152.28493 | AJ5: =W5*B$20/(B$20-1) -> 386.48914 | AK5: =B$45*AG5 -> 522.90341 | AL5: =AT5-AU5*W5 -> 6581489.6 | AM5: =B$47+B$50*MAX(0, AL5 )+B$49 *AF5 -> 230261.08 | AN5: =AM5/(B$48+AM5) -> 0.99967249 | AO5: =B$36*AP5 -> 31.443576 | AP5: =$B$10*(1 + $B$51*LN(1 + AX5/$B$12)) -> 116.59885 | AQ5: =B$54*K5*(1-Z5) -> 0.00070441491 | AR5: =Z5*B$52 -> 7.7925713e-05 | AS5: =X5/B$6 -> 40.171004 | AT5: =AU5*AG5 -> 15300166 | AU5: =F5*B$59*O5 -> 34660.216 | AV5: =AV4+AU4*B$3 -> 3925.7791 | AW5: =B$11*(AG5/B$9)*(1 - B$55*MIN(1,V5)) -> 116.77281 | AX5: =AU5*B$61*(1-Z5) -> 34281.464 | AY5: =AY4+AL5*B$3 -> 800316.63 | AZ5: =AU5*B$61 -> 34456.255 | BA5: =AZ5*Z5 -> 174.79135 | BB5: =AX5*B$60+BA5*B$53 -> 68687.595 | BC5: =BC4+BB4*B$3 -> 7780.16
A6: (05) AVERAGE LIFE= | B6: =Model_BAU!B6 -> 0.89290336 | C6: =Interface!C6 -> 0.89290336 | D6: Units: Year | E6: =E5+B$3 -> 2000.1875 | F6: =B$4*AD6*G6*(B$9/AG6)^B$20*((B$42-X6)/B$5) -> 269.14749 | G6: =1/(1 + AW6/B$18) -> 0.90683011 | H6: =H5+B$3*I5 -> 3045.6287 | I6: =(R6-H6)/B$32 -> 14368.658 | J6: =(S6-U6)/B$57 -> 0.11550362 | K6: =K5+B$3*(L5-M5) -> 0.028470139 | L6: =B$15 * (Q6 + AN6) * (1 - K6) -> 0.019274981 | M6: =K6*B$14 -> 0.00032046959 | N6: =B$16 + B$17*U6 -> 0.27773643 | O6: =AA6 -> 0.33860482 | P6: =B$21*AB6 -> 0.087472089 | Q6: =P6/(B$22+P6) -> 0.052730502 | R6: =MAX(0,AL6*B$33) -> 10240.553 | S6: =B$56 + B$58 * MIN(1, MAX(0, AL6)/B$46) -> 0.79972799 | T6: =MIN(1,B$23+B$24*Z6) -> 0.20399443 | U6: =U5+B$3*J5 -> 0.22220985 | V6: =MIN(1, H6/(B$13 + H6)) -> 0.79273741 | W6: =MAX(B$8*$B$7, $B$7*(1 - $B$34*LN(1 + Y6))) + AO6 -> 246.32896 | X6: =X5+B$3*(F5-AS5) -> 49.382435 | Y6: =X6/B$28 -> 5.4491251 | Z6: =Z5+B$3*(AQ5-AR5) -> 0.0051120037 | AA6: =AA5+B$3*(AE5-AC5) -> 0.33860482 | AB6: =X6*B$19 -> 103.76921 | AC6: =AA6*B$39 -> 0.0052302363 | AD6: =MIN(1,AA6^B$41) -> 0.088183794 | AE6: =B$40*P6*(1-AA6) -> 0.00069142115 | AF6: =B$43*T6 -> 0.20179619 | AG6: =AG5+(AH5+AI5-AK5)*B$3 -> 434.62927 | AH6: =AG6*B$44 -> 257.72317 | AI6: =B$35*MIN(B$37*B$9,MAX(B$38*B$9,AJ6)) -> 152.28493 | AJ6: =W6*B$20/(B$20-1) -> 378.47177 | AK6: =B$45*AG6 -> 514.84391 | AL6: =AT6-AU6*W6 -> 6845330.6 | AM6: =B$47+B$50*MAX(0, AL6 )+B$49 *AF6 -> 239491.41 | AN6: =AM6/(B$48+AM6) -> 0.99968511 | AO6: =B$36*AP6 -> 31.502051 | AP6: =$B$10*(1 + $B$51*LN(1 + AX6/$B$12)) -> 116.81568 | AQ6: =B$54*K6*(1-Z6) -> 0.0007346026 | AR6: =Z6*B$52 -> 7.8527195e-05 | AS6: =X6/B$6 -> 55.305464 | AT6: =AU6*AG6 -> 15800192 | AU6: =F6*B$59*O6 -> 36353.262 | AV6: =AV5+AU5*B$3 -> 6092.0426 | AW6: =B$11*(AG6/B$9)*(1 - B$55*MIN(1,V6)) -> 108.677 | AX6: =AU6*B$61*(1-Z6) -> 35954.594 | AY6: =AY5+AL6*B$3 -> 1228149.8 | AZ6: =AU6*B$61 -> 36139.338 | BA6: =AZ6*Z6 -> 184.74443 | BB6: =AX6*B$60+BA6*B$53 -> 72040.905 | BC6: =BC5+BB5*B$3 -> 12073.135
A7: (06) BASE COST= | B7: =Model_BAU!B7 -> 252.23051 | C7: =Interface!C7 -> 252.23051 | D7: Units: Dollars/Units | E7: =E6+B$3 -> 2000.25 | F7: =B$4*AD7*G7*(B$9/AG7)^B$20*((B$42-X7)/B$5) -> 281.57828 | G7: =1/(1 + AW7/B$18) -> 0.9108263 | H7: =H6+B$3*I6 -> 3943.6698 | I7: =(R7-H7)/B$32 -> 13220.968 | J7: =(S7-U7)/B$57 -> 0.11405983 | K7: =K6+B$3*(L6-M6) -> 0.029654796 | L7: =B$15 * (Q7 + AN7) * (1 - K7) -> 0.019495468 | M7: =K7*B$14 -> 0.0003338045 | N7: =B$16 + B$17*U7 -> 0.28351059 | O7: =AA7 -> 0.33832114 | P7: =B$21*AB7 -> 0.111146 | Q7: =P7/(B$22+P7) -> 0.066059022 | R7: =MAX(0,AL7*B$33) -> 10563.903 | S7: =B$56 + B$58 * MIN(1, MAX(0, AL7)/B$46) -> 0.79972799 | T7: =MIN(1,B$23+B$24*Z7) -> 0.20402724 | U7: =U6+B$3*J6 -> 0.22942882 | V7: =MIN(1, H7/(B$13 + H7)) -> 0.83200578 | W7: =MAX(B$8*$B$7, $B$7*(1 - $B$34*LN(1 + Y7))) + AO7 -> 242.25072 | X7: =X6+B$3*(F6-AS6) -> 62.747561 | Y7: =X7/B$28 -> 6.9239056 | Z7: =Z6+B$3*(AQ6-AR6) -> 0.0051530084 | AA7: =AA6+B$3*(AE6-AC6) -> 0.33832114 | AB7: =X7*B$19 -> 131.85387 | AC7: =AA7*B$39 -> 0.0052258546 | AD7: =MIN(1,AA7^B$41) -> 0.088018216 | AE7: =B$40*P7*(1-AA7) -> 0.00087892789 | AF7: =B$43*T7 -> 0.20182865 | AG7: =AG6+(AH6+AI6-AK6)*B$3 -> 428.07704 | AH7: =AG7*B$44 -> 253.83788 | AI7: =B$35*MIN(B$37*B$9,MAX(B$38*B$9,AJ7)) -> 152.28493 | AJ7: =W7*B$20/(B$20-1) -> 372.20576 | AK7: =B$45*AG7 -> 507.0824 | AL7: =AT7-AU7*W7 -> 7061474.9 | AM7: =B$47+B$50*MAX(0, AL7 )+B$49 *AF7 -> 247053.1 | AN7: =AM7/(B$48+AM7) -> 0.99969474 | AO7: =B$36*AP7 -> 31.556384 | AP7: =$B$10*(1 + $B$51*LN(1 + AX7/$B$12)) -> 117.01716 | AQ7: =B$54*K7*(1-Z7) -> 0.00076513825 | AR7: =Z7*B$52 -> 7.9157082e-05 | AS7: =X7/B$6 -> 70.273631 | AT7: =AU7*AG7 -> 16267100 | AU7: =F7*B$59*O7 -> 38000.403 | AV7: =AV6+AU6*B$3 -> 8364.1215 | AW7: =B$11*(AG7/B$9)*(1 - B$55*MIN(1,V7)) -> 103.55933 | AX7: =AU7*B$61*(1-Z7) -> 37582.123 | AY7: =AY6+AL7*B$3 -> 1669492 | AZ7: =AU7*B$61 -> 37776.787 | BA7: =AZ7*Z7 -> 194.6641 | BB7: =AX7*B$60+BA7*B$53 -> 75302.984 | BC7: =BC6+BB6*B$3 -> 16575.691
A8: BASE COST MULTIPLER | B8: =Model_BAU!B8 -> 0.2989792 | C8: =Interface!C8 -> 0.2989792 | D8: Units: Dmnl | E8: =E7+B$3 -> 2000.3125 | F8: =B$4*AD8*G8*(B$9/AG8)^B$20*((B$42-X8)/B$5) -> 293.96821 | G8: =1/(1 + AW8/B$18) -> 0.91374031 | H8: =H7+B$3*I7 -> 4769.9803 | I8: =(R8-H8)/B$32 -> 12129.169 | J8: =(S8-U8)/B$57 -> 0.11263408 | K8: =K7+B$3*(L7-M7) -> 0.0308524 | L8: =B$15 * (Q8 + AN8) * (1 - K8) -> 0.019705536 | M8: =K8*B$14 -> 0.00034728514 | N8: =B$16 + B$17*U8 -> 0.28921257 | O8: =AA8 -> 0.33804946 | P8: =B$21*AB8 -> 0.13453901 | Q8: =P8/(B$22+P8) -> 0.078866015 | R8: =MAX(0,AL8*B$33) -> 10843.509 | S8: =B$56 + B$58 * MIN(1, MAX(0, AL8)/B$46) -> 0.79972799 | T8: =MIN(1,B$23+B$24*Z8) -> 0.20406155 | U8: =U7+B$3*J7 -> 0.23655756 | V8: =MIN(1, H8/(B$13 + H8)) -> 0.85694448 | W8: =MAX(B$8*$B$7, $B$7*(1 - $B$34*LN(1 + Y8))) + AO8 -> 238.9148 | X8: =X7+B$3*(F7-AS7) -> 75.954102 | Y8: =X8/B$28 -> 8.3811868 | Z8: =Z7+B$3*(AQ7-AR7) -> 0.0051958822 | AA8: =AA7+B$3*(AE7-AC7) -> 0.33804946 | AB8: =X8*B$19 -> 159.60528 | AC8: =AA8*B$39 -> 0.005221658 | AD8: =MIN(1,AA8^B$41) -> 0.087859799 | AE8: =B$40*P8*(1-AA8) -> 0.0010643535 | AF8: =B$43*T8 -> 0.20186258 | AG8: =AG7+(AH7+AI7-AK7)*B$3 -> 421.76706 | AH8: =AG8*B$44 -> 250.09624 | AI8: =B$35*MIN(B$37*B$9,MAX(B$38*B$9,AJ8)) -> 152.28493 | AJ8: =W8*B$20/(B$20-1) -> 367.08029 | AK8: =B$45*AG8 -> 499.60786 | AL8: =AT8-AU8*W8 -> 7248378.5 | AM8: =B$47+B$50*MAX(0, AL8 )+B$49 *AF8 -> 253591.83 | AN8: =AM8/(B$48+AM8) -> 0.99970261 | AO8: =B$36*AP8 -> 31.6082 | AP8: =$B$10*(1 + $B$51*LN(1 + AX8/$B$12)) -> 117.2093 | AQ8: =B$54*K8*(1-Z8) -> 0.00079600393 | AR8: =Z8*B$52 -> 7.9815681e-05 | AS8: =X8/B$6 -> 85.064191 | AT8: =AU8*AG8 -> 16719111 | AU8: =F8*B$59*O8 -> 39640.628 | AV8: =AV7+AU7*B$3 -> 10739.147 | AW8: =B$11*(AG8/B$9)*(1 - B$55*MIN(1,V8)) -> 99.855753 | AX8: =AU8*B$61*(1-Z8) -> 39202.604 | AY8: =AY7+AL8*B$3 -> 2122515.6 | AZ8: =AU8*B$61 -> 39407.36 | BA8: =AZ8*Z8 -> 204.756 | BB8: =AX8*B$60+BA8*B$53 -> 78551.082 | BC8: =BC7+BB7*B$3 -> 21282.128
A9: (92) BASE PRICE= | B9: =Model_BAU!B9 -> 455.83438 | C9: =Interface!C9 -> 455.83438 | D9: Units: Dollars/Units | E9: =E8+B$3 -> 2000.375 | F9: =B$4*AD9*G9*(B$9/AG9)^B$20*((B$42-X9)/B$5) -> 306.42669 | G9: =1/(1 + AW9/B$18) -> 0.91604626 | H9: =H8+B$3*I8 -> 5528.0534 | I9: =(R9-H9)/B$32 -> 11113.557 | J9: =(S9-U9)/B$57 -> 0.11122615 | K9: =K8+B$3*(L8-M8) -> 0.032062291 | L9: =B$15 * (Q9 + AN9) * (1 - K9) -> 0.019905879 | M9: =K9*B$14 -> 0.00036090408 | N9: =B$16 + B$17*U9 -> 0.29484328 | O9: =AA9 -> 0.33778963 | P9: =B$21*AB9 -> 0.15766625 | Q9: =P9/(B$22+P9) -> 0.091186849 | R9: =MAX(0,AL9*B$33) -> 11093.027 | S9: =B$56 + B$58 * MIN(1, MAX(0, AL9)/B$46) -> 0.79972799 | T9: =MIN(1,B$23+B$24*Z9) -> 0.20409736 | U9: =U8+B$3*J8 -> 0.24359719 | V9: =MIN(1, H9/(B$13 + H9)) -> 0.87409197 | W9: =MAX(B$8*$B$7, $B$7*(1 - $B$34*LN(1 + Y9))) + AO9 -> 236.09786 | X9: =X8+B$3*(F8-AS8) -> 89.010603 | Y9: =X9/B$28 -> 9.8219118 | Z9: =Z8+B$3*(AQ8-AR8) -> 0.005240644 | AA9: =AA8+B$3*(AE8-AC8) -> 0.33778963 | AB9: =X9*B$19 -> 187.04141 | AC9: =AA9*B$39 -> 0.0052176446 | AD9: =MIN(1,AA9^B$41) -> 0.087708441 | AE9: =B$40*P9*(1-AA9) -> 0.0012478054 | AF9: =B$43*T9 -> 0.20189801 | AG9: =AG8+(AH8+AI8-AK8)*B$3 -> 415.69039 | AH9: =AG9*B$44 -> 246.49294 | AI9: =B$35*MIN(B$37*B$9,MAX(B$38*B$9,AJ9)) -> 152.28493 | AJ9: =W9*B$20/(B$20-1) -> 362.75221 | AK9: =B$45*AG9 -> 492.40969 | AL9: =AT9-AU9*W9 -> 7415169.6 | AM9: =B$47+B$50*MAX(0, AL9 )+B$49 *AF9 -> 259426.92 | AN9: =AM9/(B$48+AM9) -> 0.9997093 | AO9: =B$36*AP9 -> 31.658152 | AP9: =$B$10*(1 + $B$51*LN(1 + AX9/$B$12)) -> 117.39454 | AQ9: =B$54*K9*(1-Z9) -> 0.00082718236 | AR9: =Z9*B$52 -> 8.0503282e-05 | AS9: =X9/B$6 -> 99.686715 | AT9: =AU9*AG9 -> 17163379 | AU9: =F9*B$59*O9 -> 41288.852 | AV9: =AV8+AU8*B$3 -> 13216.686 | AW9: =B$11*(AG9/B$9)*(1 - B$55*MIN(1,V9)) -> 96.941703 | AX9: =AU9*B$61*(1-Z9) -> 40830.778 | AY9: =AY8+AL9*B$3 -> 2585963.7 | AZ9: =AU9*B$61 -> 41045.885 | BA9: =AZ9*Z9 -> 215.10687 | BB9: =AX9*B$60+BA9*B$53 -> 81814.743 | BC9: =BC8+BB8*B$3 -> 26191.57
A10: (07) BASE RAW MATERIAL PRICES= | B10: =Model_BAU!B10 -> 89.96988 | C10: =Interface!C10 -> 89.96988 | D10: Units: Dollars/Tons | E10: =E9+B$3 -> 2000.4375 | F10: =B$4*AD10*G10*(B$9/AG10)^B$20*((B$42-X10)/B$5) -> 318.99984 | G10: =1/(1 + AW10/B$18) -> 0.91797145 | H10: =H9+B$3*I9 -> 6222.6507 | I10: =(R10-H10)/B$32 -> 10180.01 | J10: =(S10-U10)/B$57 -> 0.10983582 | K10: =K9+B$3*(L9-M9) -> 0.033283852 | L10: =B$15 * (Q10 + AN10) * (1 - K10) -> 0.020097239 | M10: =K10*B$14 -> 0.00037465438 | N10: =B$16 + B$17*U10 -> 0.3004036 | O10: =AA10 -> 0.33754151 | P10: =B$21*AB10 -> 0.18055392 | Q10: =P10/(B$22+P10) -> 0.10305979 | R10: =MAX(0,AL10*B$33) -> 11320.162 | S10: =B$56 + B$58 * MIN(1, MAX(0, AL10)/B$46) -> 0.79972799 | T10: =MIN(1,B$23+B$24*Z10) -> 0.20413471 | U10: =U9+B$3*J9 -> 0.25054883 | V10: =MIN(1, H10/(B$13 + H10)) -> 0.88655189 | W10: =MAX(B$8*$B$7, $B$7*(1 - $B$34*LN(1 + Y10))) + AO10 -> 233.66266 | X10: =X9+B$3*(F9-AS9) -> 101.93185 | Y10: =X10/B$28 -> 11.247712 | Z10: =Z9+B$3*(AQ9-AR9) -> 0.0052873114 | AA10: =AA9+B$3*(AE9-AC9) -> 0.33754151 | AB10: =X10*B$19 -> 214.19332 | AC10: =AA10*B$39 -> 0.0052138121 | AD10: =MIN(1,AA10^B$41) -> 0.087564044 | AE10: =B$40*P10*(1-AA10) -> 0.0014294788 | AF10: =B$43*T10 -> 0.20193495 | AG10: =AG9+(AH9+AI9-AK9)*B$3 -> 409.8384 | AH10: =AG10*B$44 -> 243.02287 | AI10: =B$35*MIN(B$37*B$9,MAX(B$38*B$9,AJ10)) -> 152.28493 | AJ10: =W10*B$20/(B$20-1) -> 359.01065 | AK10: =B$45*AG10 -> 485.47767 | AL10: =AT10-AU10*W10 -> 7566998.9 | AM10: =B$47+B$50*MAX(0, AL10 )+B$49 *AF10 -> 264738.59 | AN10: =AM10/(B$48+AM10) -> 0.99971513 | AO10: =B$36*AP10 -> 31.70656 | AP10: =$B$10*(1 + $B$51*LN(1 + AX10/$B$12)) -> 117.57404 | AQ10: =B$54*K10*(1-Z10) -> 0.0008586574 | AR10: =Z10*B$52 -> 8.1220156e-05 | AS10: =X10/B$6 -> 114.15776 | AT10: =AU10*AG10 -> 17603143 | AU10: =F10*B$59*O10 -> 42951.424 | AV10: =AV9+AU9*B$3 -> 15797.239 | AW10: =B$11*(AG10/B$9)*(1 - B$55*MIN(1,V10)) -> 94.520026 | AX10: =AU10*B$61*(1-Z10) -> 42472.911 | AY10: =AY9+AL10*B$3 -> 3058901.2 | AZ10: =AU10*B$61 -> 42698.673 | BA10: =AZ10*Z10 -> 225.76118 | BB10: =AX10*B$60+BA10*B$53 -> 85106.532 | BC10: =BC9+BB9*B$3 -> 31304.992
A11: (08) BASE UPFRONT= | B11: =Model_BAU!B11 -> 188.77296 | C11: =Interface!C11 -> 188.77296 | D11: Units: Dollars/Units | E11: =E10+B$3 -> 2000.5 | F11: =B$4*AD11*G11*(B$9/AG11)^B$20*((B$42-X11)/B$5) -> 331.70657 | G11: =1/(1 + AW11/B$18) -> 0.91963835 | H11: =H10+B$3*I10 -> 6858.9014 | I11: =(R11-H11)/B$32 -> 9327.7873 | J11: =(S11-U11)/B$57 -> 0.10846288 | K11: =K10+B$3*(L10-M10) -> 0.034516513 | L11: =B$15 * (Q11 + AN11) * (1 - K11) -> 0.020280325 | M11: =K11*B$14 -> 0.00038852964 | N11: =B$16 + B$17*U11 -> 0.30589442 | O11: =AA11 -> 0.33730499 | P11: =B$21*AB11 -> 0.20323147 | Q11: =P11/(B$22+P11) -> 0.11452169 | R11: =MAX(0,AL11*B$33) -> 11529.673 | S11: =B$56 + B$58 * MIN(1, MAX(0, AL11)/B$46) -> 0.79972799 | T11: =MIN(1,B$23+B$24*Z11) -> 0.20417358 | U11: =U10+B$3*J10 -> 0.25741357 | V11: =MIN(1, H11/(B$13 + H11)) -> 0.89598098 | W11: =MAX(B$8*$B$7, $B$7*(1 - $B$34*LN(1 + Y11))) + AO11 -> 231.51912 | X11: =X10+B$3*(F10-AS10) -> 114.73448 | Y11: =X11/B$28 -> 12.660424 | Z11: =Z10+B$3*(AQ10-AR10) -> 0.0053359012 | AA11: =AA10+B$3*(AE10-AC10) -> 0.33730499 | AB11: =X11*B$19 -> 241.09598 | AC11: =AA11*B$39 -> 0.0052101587 | AD11: =MIN(1,AA11^B$41) -> 0.087426516 | AE11: =B$40*P11*(1-AA11) -> 0.0016095957 | AF11: =B$43*T11 -> 0.20197341 | AG11: =AG10+(AH10+AI10-AK10)*B$3 -> 404.20279 | AH11: =AG11*B$44 -> 239.68111 | AI11: =B$35*MIN(B$37*B$9,MAX(B$38*B$9,AJ11)) -> 152.28493 | AJ11: =W11*B$20/(B$20-1) -> 355.71721 | AK11: =B$45*AG11 -> 478.80195 | AL11: =AT11-AU11*W11 -> 7707047.2 | AM11: =B$47+B$50*MAX(0, AL11 )+B$49 *AF11 -> 269638.11 | AN11: =AM11/(B$48+AM11) -> 0.99972031 | AO11: =B$36*AP11 -> 31.753596 | AP11: =$B$10*(1 + $B$51*LN(1 + AX11/$B$12)) -> 117.74846 | AQ11: =B$54*K11*(1-Z11) -> 0.00089041413 | AR11: =Z11*B$52 -> 8.1966561e-05 | AS11: =X11/B$6 -> 128.49597 | AT11: =AU11*AG11 -> 18039980 | AU11: =F11*B$59*O11 -> 44631.014 | AV11: =AV10+AU10*B$3 -> 18481.703 | AW11: =B$11*(AG11/B$9)*(1 - B$55*MIN(1,V11)) -> 92.431441 | AX11: =AU11*B$61*(1-Z11) -> 44131.634 | AY11: =AY10+AL11*B$3 -> 3540591.6 | AZ11: =AU11*B$61 -> 44368.38 | BA11: =AZ11*Z11 -> 236.74529 | BB11: =AX11*B$60+BA11*B$53 -> 88431.727 | BC11: =BC10+BB10*B$3 -> 36624.15
A12: (09) BASELINE VIRGIN DEMAND= | B12: =Model_BAU!B12 -> 100.48156 | C12: =Interface!C12 -> 100.48156 | D12: Units: Tons/Year | E12: =E11+B$3 -> 2000.5625 | F12: =B$4*AD12*G12*(B$9/AG12)^B$20*((B$42-X12)/B$5) -> 344.55248 | G12: =1/(1 + AW12/B$18) -> 0.92111883 | H12: =H11+B$3*I11 -> 7441.8881 | I12: =(R12-H12)/B$32 -> 8553.0114 | J12: =(S12-U12)/B$57 -> 0.10710709 | K12: =K11+B$3*(L11-M11) -> 0.035759751 | L12: =B$15 * (Q12 + AN12) * (1 - K12) -> 0.020455789 | M12: =K12*B$14 -> 0.00040252394 | N12: =B$16 + B$17*U12 -> 0.3113166 | O12: =AA12 -> 0.33707996 | P12: =B$21*AB12 -> 0.22572841 | Q12: =P12/(B$22+P12) -> 0.12560647 | R12: =MAX(0,AL12*B$33) -> 11724.701 | S12: =B$56 + B$58 * MIN(1, MAX(0, AL12)/B$46) -> 0.79972799 | T12: =MIN(1,B$23+B$24*Z12) -> 0.20421401 | U12: =U11+B$3*J11 -> 0.2641925 | V12: =MIN(1, H12/(B$13 + H12)) -> 0.90334204 | W12: =MAX(B$8*$B$7, $B$7*(1 - $B$34*LN(1 + Y12))) + AO12 -> 229.60507 | X12: =X11+B$3*(F11-AS11) -> 127.43514 | Y12: =X12/B$28 -> 14.061884 | Z12: =Z11+B$3*(AQ11-AR11) -> 0.0053864292 | AA12: =AA11+B$3*(AE11-AC11) -> 0.33707996 | AB12: =X12*B$19 -> 267.78437 | AC12: =AA12*B$39 -> 0.0052066827 | AD12: =MIN(1,AA12^B$41) -> 0.087295778 | AE12: =B$40*P12*(1-AA12) -> 0.0017883787 | AF12: =B$43*T12 -> 0.20201341 | AG12: =AG11+(AH11+AI11-AK11)*B$3 -> 398.77554 | AH12: =AG12*B$44 -> 236.4629 | AI12: =B$35*MIN(B$37*B$9,MAX(B$38*B$9,AJ12)) -> 152.28493 | AJ12: =W12*B$20/(B$20-1) -> 352.77637 | AK12: =B$45*AG12 -> 472.37306 | AL12: =AT12-AU12*W12 -> 7837413.9 | AM12: =B$47+B$50*MAX(0, AL12 )+B$49 *AF12 -> 274198.92 | AN12: =AM12/(B$48+AM12) -> 0.99972496 | AO12: =B$36*AP12 -> 31.799369 | AP12: =$B$10*(1 + $B$51*LN(1 + AX12/$B$12)) -> 117.91819 | AQ12: =B$54*K12*(1-Z12) -> 0.00092243876 | AR12: =Z12*B$52 -> 8.2742738e-05 | AS12: =X12/B$6 -> 142.71997 | AT12: =AU12*AG12 -> 18474672 | AU12: =F12*B$59*O12 -> 46328.498 | AV12: =AV11+AU11*B$3 -> 21271.142 | AW12: =B$11*(AG12/B$9)*(1 - B$55*MIN(1,V12)) -> 90.582789 | AX12: =AU12*B$61*(1-Z12) -> 45807.798 | AY12: =AY11+AL12*B$3 -> 4030430 | AZ12: =AU12*B$61 -> 46055.874 | BA12: =AZ12*Z12 -> 248.07671 | BB12: =AX12*B$60+BA12*B$53 -> 91792.041 | BC12: =BC11+BB11*B$3 -> 42151.133
A13: (11) CAPITAL NORM= | B13: =Model_BAU!B13 -> 796.28499 | C13: =Interface!C13 -> 796.28499 | D13: Units: Dollars/Year | E13: =E12+B$3 -> 2000.625 | F13: =B$4*AD13*G13*(B$9/AG13)^B$20*((B$42-X13)/B$5) -> 357.53591 | G13: =1/(1 + AW13/B$18) -> 0.92245791 | H13: =H12+B$3*I12 -> 7976.4513 | I13: =(R13-H13)/B$32 -> 7850.3803 | J13: =(S13-U13)/B$57 -> 0.10576825 | K13: =K12+B$3*(L12-M12) -> 0.03701308 | L13: =B$15 * (Q13 + AN13) * (1 - K13) -> 0.020624219 | M13: =K13*B$14 -> 0.00041663184 | N13: =B$16 + B$17*U13 -> 0.31667101 | O13: =AA13 -> 0.33686631 | P13: =B$21*AB13 -> 0.24807278 | Q13: =P13/(B$22+P13) -> 0.13634474 | R13: =MAX(0,AL13*B$33) -> 11907.43 | S13: =B$56 + B$58 * MIN(1, MAX(0, AL13)/B$46) -> 0.79972799 | T13: =MIN(1,B$23+B$24*Z13) -> 0.20425601 | U13: =U12+B$3*J12 -> 0.27088669 | V13: =MIN(1, H13/(B$13 + H13)) -> 0.90923186 | W13: =MAX(B$8*$B$7, $B$7*(1 - $B$34*LN(1 + Y13))) + AO13 -> 227.87591 | X13: =X12+B$3*(F12-AS12) -> 140.04968 | Y13: =X13/B$28 -> 15.453839 | Z13: =Z12+B$3*(AQ12-AR12) -> 0.0054389102 | AA13: =AA12+B$3*(AE12-AC12) -> 0.33686631 | AB13: =X13*B$19 -> 294.29177 | AC13: =AA13*B$39 -> 0.0052033826 | AD13: =MIN(1,AA13^B$41) -> 0.087171758 | AE13: =B$40*P13*(1-AA13) -> 0.0019660399 | AF13: =B$43*T13 -> 0.20205495 | AG13: =AG12+(AH12+AI12-AK12)*B$3 -> 393.54897 | AH13: =AG13*B$44 -> 233.36369 | AI13: =B$35*MIN(B$37*B$9,MAX(B$38*B$9,AJ13)) -> 152.28493 | AJ13: =W13*B$20/(B$20-1) -> 350.1196 | AK13: =B$45*AG13 -> 466.18187 | AL13: =AT13-AU13*W13 -> 7959560.1 | AM13: =B$47+B$50*MAX(0, AL13 )+B$49 *AF13 -> 278472.14 | AN13: =AM13/(B$48+AM13) -> 0.99972918 | AO13: =B$36*AP13 -> 31.843948 | AP13: =$B$10*(1 + $B$51*LN(1 + AX13/$B$12)) -> 118.0835 | AQ13: =B$54*K13*(1-Z13) -> 0.00095471856 | AR13: =Z13*B$52 -> 8.3548916e-05 | AS13: =X13/B$6 -> 156.84752 | AT13: =AU13*AG13 -> 18907580 | AU13: =F13*B$59*O13 -> 48043.78 | AV13: =AV12+AU12*B$3 -> 24166.673 | AW13: =B$11*(AG13/B$9)*(1 - B$55*MIN(1,V13)) -> 88.915795 | AX13: =AU13*B$61*(1-Z13) -> 47501.294 | AY13: =AY12+AL13*B$3 -> 4527902.5 | AZ13: =AU13*B$61 -> 47761.062 | BA13: =AZ13*Z13 -> 259.76813 | BB13: =AX13*B$60+BA13*B$53 -> 95187.27 | BC13: =BC12+BB12*B$3 -> 47888.136
A14: (17) CIRCULAR DESIGN DECAY RATE= | B14: =Model_BAU!B14 -> 0.011256341 | C14: =Interface!C14 -> 0.22512682 | D14: Units: 1/Year | E14: =E13+B$3 -> 2000.6875 | F14: =B$4*AD14*G14*(B$9/AG14)^B$20*((B$42-X14)/B$5) -> 370.65101 | G14: =1/(1 + AW14/B$18) -> 0.92368538 | H14: =H13+B$3*I13 -> 8467.1 | I14: =(R14-H14)/B$32 -> 7214.063 | J14: =(S14-U14)/B$57 -> 0.10444615 | K14: =K13+B$3*(L13-M13) -> 0.038276054 | L14: =B$15 * (Q14 + AN14) * (1 - K14) -> 0.020786138 | M14: =K14*B$14 -> 0.00043084831 | N14: =B$16 + B$17*U14 -> 0.32195849 | O14: =AA14 -> 0.33666398 | P14: =B$21*AB14 -> 0.27029049 | Q14: =P14/(B$22+P14) -> 0.14676378 | R14: =MAX(0,AL14*B$33) -> 12079.451 | S14: =B$56 + B$58 * MIN(1, MAX(0, AL14)/B$46) -> 0.79972799 | T14: =MIN(1,B$23+B$24*Z14) -> 0.20429957 | U14: =U13+B$3*J13 -> 0.2774972 | V14: =MIN(1, H14/(B$13 + H14)) -> 0.91403952 | W14: =MAX(B$8*$B$7, $B$7*(1 - $B$34*LN(1 + Y14))) + AO14 -> 226.2986 | X14: =X13+B$3*(F13-AS13) -> 152.5927 | Y14: =X14/B$28 -> 16.837905 | Z14: =Z13+B$3*(AQ13-AR13) -> 0.0054933583 | AA14: =AA13+B$3*(AE13-AC13) -> 0.33666398 | AB14: =X14*B$19 -> 320.64891 | AC14: =AA14*B$39 -> 0.0052002573 | AD14: =MIN(1,AA14^B$41) -> 0.087054394 | AE14: =B$40*P14*(1-AA14) -> 0.0021427745 | AF14: =B$43*T14 -> 0.20209804 | AG14: =AG13+(AH13+AI13-AK13)*B$3 -> 388.51564 | AH14: =AG14*B$44 -> 230.37906 | AI14: =B$35*MIN(B$37*B$9,MAX(B$38*B$9,AJ14)) -> 152.28493 | AJ14: =W14*B$20/(B$20-1) -> 347.69615 | AK14: =B$45*AG14 -> 460.2196 | AL14: =AT14-AU14*W14 -> 8074548 | AM14: =B$47+B$50*MAX(0, AL14 )+B$49 *AF14 -> 282494.93 | AN14: =AM14/(B$48+AM14) -> 0.99973303 | AO14: =B$36*AP14 -> 31.887385 | AP14: =$B$10*(1 + $B$51*LN(1 + AX14/$B$12)) -> 118.24457 | AQ14: =B$54*K14*(1-Z14) -> 0.00098724178 | AR14: =Z14*B$52 -> 8.4385311e-05 | AS14: =X14/B$6 -> 170.89498 | AT14: =AU14*AG14 -> 19338833 | AU14: =F14*B$59*O14 -> 49776.202 | AV14: =AV13+AU13*B$3 -> 27169.409 | AW14: =B$11*(AG14/B$9)*(1 - B$55*MIN(1,V14)) -> 87.39199 | AX14: =AU14*B$61*(1-Z14) -> 49211.46 | AY14: =AY13+AL14*B$3 -> 5032561.7 | AZ14: =AU14*B$61 -> 49483.29 | BA14: =AZ14*Z14 -> 271.82944 | BB14: =AX14*B$60+BA14*B$53 -> 98616.092 | BC14: =BC13+BB13*B$3 -> 53837.34
A15: (18) CIRCULAR DESIGN GAIN= | B15: =Model_BAU!B15 -> 0.018851701 | C15: =Interface!C15 -> 0.37703401 | D15: Units: 1/Year | E15: =E14+B$3 -> 2000.75 | F15: =B$4*AD15*G15*(B$9/AG15)^B$20*((B$42-X15)/B$5) -> 383.88932 | G15: =1/(1 + AW15/B$18) -> 0.9248218 | H15: =H14+B$3*I14 -> 8917.979 | I15: =(R15-H15)/B$32 -> 6638.1796 | J15: =(S15-U15)/B$57 -> 0.10314057 | K15: =K14+B$3*(L14-M14) -> 0.039548259 | L15: =B$15 * (Q15 + AN15) * (1 - K15) -> 0.020942012 | M15: =K15*B$14 -> 0.00044516869 | N15: =B$16 + B$17*U15 -> 0.32717987 | O15: =AA15 -> 0.33647288 | P15: =B$21*AB15 -> 0.29240498 | Q15: =P15/(B$22+P15) -> 0.15688774 | R15: =MAX(0,AL15*B$33) -> 12241.964 | S15: =B$56 + B$58 * MIN(1, MAX(0, AL15)/B$46) -> 0.79972799 | T15: =MIN(1,B$23+B$24*Z15) -> 0.20434472 | U15: =U14+B$3*J14 -> 0.28402509 | V15: =MIN(1, H15/(B$13 + H15)) -> 0.9180293 | W15: =MAX(B$8*$B$7, $B$7*(1 - $B$34*LN(1 + Y15))) + AO15 -> 224.84809 | X15: =X14+B$3*(F14-AS14) -> 165.07745 | Y15: =X15/B$28 -> 18.21554 | Z15: =Z14+B$3*(AQ14-AR14) -> 0.0055497869 | AA15: =AA14+B$3*(AE14-AC14) -> 0.33647288 | AB15: =X15*B$19 -> 346.88361 | AC15: =AA15*B$39 -> 0.0051973056 | AD15: =MIN(1,AA15^B$41) -> 0.08694363 | AE15: =B$40*P15*(1-AA15) -> 0.0023187588 | AF15: =B$43*T15 -> 0.20214271 | AG15: =AG14+(AH14+AI14-AK14)*B$3 -> 383.66841 | AH15: =AG15*B$44 -> 227.50479 | AI15: =B$35*MIN(B$37*B$9,MAX(B$38*B$9,AJ15)) -> 152.28493 | AJ15: =W15*B$20/(B$20-1) -> 345.46751 | AK15: =B$45*AG15 -> 454.47778 | AL15: =AT15-AU15*W15 -> 8183180.1 | AM15: =B$47+B$50*MAX(0, AL15 )+B$49 *AF15 -> 286295.36 | AN15: =AM15/(B$48+AM15) -> 0.99973657 | AO15: =B$36*AP15 -> 31.929718 | AP15: =$B$10*(1 + $B$51*LN(1 + AX15/$B$12)) -> 118.40155 | AQ15: =B$54*K15*(1-Z15) -> 0.0010199975 | AR15: =Z15*B$52 -> 8.5252129e-05 | AS15: =X15/B$6 -> 184.87718 | AT15: =AU15*AG15 -> 19768425 | AU15: =F15*B$59*O15 -> 51524.765 | AV15: =AV14+AU14*B$3 -> 30280.422 | AW15: =B$11*(AG15/B$9)*(1 - B$55*MIN(1,V15)) -> 85.984828 | AX15: =AU15*B$61*(1-Z15) -> 50937.294 | AY15: =AY14+AL15*B$3 -> 5544010.5 | AZ15: =AU15*B$61 -> 51221.563 | BA15: =AZ15*Z15 -> 284.26876 | BB15: =AX15*B$60+BA15*B$53 -> 102076.51 | BC15: =BC14+BB14*B$3 -> 60000.846
... A61: (91) VIRGIN PER UNIT= | B61: =Model_BAU!B61 -> 0.99411542 | C61: =Interface!C61 -> 0.99411542 | D61: Units: Tons/Units | E61: =E60+B$3 -> 2003.625 | F61: =B$4*AD61*G61*(B$9/AG61)^B$20*((B$42-X61)/B$5) -> 953.08357 | G61: =1/(1 + AW61/B$18) -> 0.94564603 | H61: =H60+B$3*I60 -> 15364.598 | I61: =(R61-H61)/B$32 -> 967.64213 | J61: =(S61-U61)/B$57 -> 0.057827758 | K61: =K60+B$3*(L60-M60) -> 0.10373509 | L61: =B$15 * (Q61 + AN61) * (1 - K61) -> 0.024387147 | M61: =K61*B$14 -> 0.0011676776 | N61: =B$16 + B$17*U61 -> 0.50839908 | O61: =AA61 -> 0.33926042 | P61: =B$21*AB61 -> 1.2526157 | Q61: =P61/(B$22+P61) -> 0.44356152 | R61: =MAX(0,AL61*B$33) -> 15849.132 | S61: =B$56 + B$58 * MIN(1, MAX(0, AL61)/B$46) -> 0.79972799 | T61: =MIN(1,B$23+B$24*Z61) -> 0.20823879 | U61: =U60+B$3*J60 -> 0.51058918 | V61: =MIN(1, H61/(B$13 + H61)) -> 0.95072763 | W61: =MAX(B$8*$B$7, $B$7*(1 - $B$34*LN(1 + Y61))) + AO61 -> 197.59243 | X61: =X60+B$3*(F60-AS60) -> 707.16514 | Y61: =X61/B$28 -> 78.03243 | Z61: =Z60+B$3*(AQ60-AR60) -> 0.010416506 | AA61: =AA60+B$3*(AE60-AC60) -> 0.33926042 | AB61: =X61*B$19 -> 1485.9933 | AC61: =AA61*B$39 -> 0.005240363 | AD61: =MIN(1,AA61^B$41) -> 0.088567119 | AE61: =B$40*P61*(1-AA61) -> 0.0098914579 | AF61: =B$43*T61 -> 0.20599482 | AG61: =AG60+(AH60+AI60-AK60)*B$3 -> 279.732 | AH61: =AG61*B$44 -> 165.87336 | AI61: =B$35*MIN(B$37*B$9,MAX(B$38*B$9,AJ61)) -> 152.28493 | AJ61: =W61*B$20/(B$20-1) -> 303.59059 | AK61: =B$45*AG61 -> 331.35898 | AL61: =AT61-AU61*W61 -> 10594403 | AM61: =B$47+B$50*MAX(0, AL61 )+B$49 *AF61 -> 370650.75 | AN61: =AM61/(B$48+AM61) -> 0.99979651 | AO61: =B$36*AP61 -> 33.051455 | AP61: =$B$10*(1 + $B$51*LN(1 + AX61/$B$12)) -> 122.56117 | AQ61: =B$54*K61*(1-Z61) -> 0.0026623603 | AR61: =Z61*B$52 -> 0.00016001143 | AS61: =X61/B$6 -> 791.98396 | AT61: =AU61*AG61 -> 36079976 | AU61: =F61*B$59*O61 -> 128980.51 | AV61: =AV60+AU60*B$3 -> 292269.07 | AW61: =B$11*(AG61/B$9)*(1 - B$55*MIN(1,V61)) -> 60.798195 | AX61: =AU61*B$61*(1-Z61) -> 126885.89 | AY61: =AY60+AL61*B$3 -> 33222213 | AZ61: =AU61*B$61 -> 128221.51 | BA61: =AZ61*Z61 -> 1335.6202 | BB61: =AX61*B$60+BA61*B$53 -> 254701.14 | BC61: =BC60+BB60*B$3 -> 578222.98
E62: =E61+B$3 -> 2003.6875 | F62: =B$4*AD62*G62*(B$9/AG62)^B$20*((B$42-X62)/B$5) -> 962.53026 | G62: =1/(1 + AW62/B$18) -> 0.94580662 | H62: =H61+B$3*I61 -> 15425.075 | I62: =(R62-H62)/B$32 -> 970.68036 | J62: =(S62-U62)/B$57 -> 0.057104911 | K62: =K61+B$3*(L61-M61) -> 0.10518631 | L62: =B$15 * (Q62 + AN62) * (1 - K62) -> 0.024406581 | M62: =K62*B$14 -> 0.001184013 | N62: =B$16 + B$17*U62 -> 0.51128995 | O62: =AA62 -> 0.33955111 | P62: =B$21*AB62 -> 1.2704506 | Q62: =P62/(B$22+P62) -> 0.44705365 | R62: =MAX(0,AL62*B$33) -> 15911.131 | S62: =B$56 + B$58 * MIN(1, MAX(0, AL62)/B$46) -> 0.79972799 | T62: =MIN(1,B$23+B$24*Z62) -> 0.20836393 | U62: =U61+B$3*J61 -> 0.51420341 | V62: =MIN(1, H62/(B$13 + H62)) -> 0.95091133 | W62: =MAX(B$8*$B$7, $B$7*(1 - $B$34*LN(1 + Y62))) + AO62 -> 197.32528 | X62: =X61+B$3*(F61-AS61) -> 717.23387 | Y62: =X62/B$28 -> 79.143468 | Z62: =Z61+B$3*(AQ61-AR61) -> 0.010572903 | AA62: =AA61+B$3*(AE61-AC61) -> 0.33955111 | AB62: =X62*B$19 -> 1507.1511 | AC62: =AA62*B$39 -> 0.0052448532 | AD62: =MIN(1,AA62^B$41) -> 0.088737381 | AE62: =B$40*P62*(1-AA62) -> 0.01002788 | AF62: =B$43*T62 -> 0.20611861 | AG62: =AG61+(AH61+AI61-AK61)*B$3 -> 278.90695 | AH62: =AG62*B$44 -> 165.38413 | AI62: =B$35*MIN(B$37*B$9,MAX(B$38*B$9,AJ62)) -> 152.28493 | AJ62: =W62*B$20/(B$20-1) -> 303.18013 | AK62: =B$45*AG62 -> 330.38167 | AL62: =AT62-AU62*W62 -> 10635847 | AM62: =B$47+B$50*MAX(0, AL62 )+B$49 *AF62 -> 372100.63 | AN62: =AM62/(B$48+AM62) -> 0.99979731 | AO62: =B$36*AP62 -> 33.064442 | AP62: =$B$10*(1 + $B$51*LN(1 + AX62/$B$12)) -> 122.60933 | AQ62: =B$54*K62*(1-Z62) -> 0.0026991791 | AR62: =Z62*B$52 -> 0.00016241389 | AS62: =X62/B$6 -> 803.26035 | AT62: =AU62*AG62 -> 36361250 | AU62: =F62*B$59*O62 -> 130370.54 | AV62: =AV61+AU61*B$3 -> 300330.35 | AW62: =B$11*(AG62/B$9)*(1 - B$55*MIN(1,V62)) -> 60.608272 | AX62: =AU62*B$61*(1-Z62) -> 128233.08 | AY62: =AY61+AL62*B$3 -> 33886954 | AZ62: =AU62*B$61 -> 129603.36 | BA62: =AZ62*Z62 -> 1370.2838 | BB62: =AX62*B$60+BA62*B$53 -> 257419.29 | BC62: =BC61+BB61*B$3 -> 594141.8
E63: =E62+B$3 -> 2003.75 | F63: =B$4*AD63*G63*(B$9/AG63)^B$20*((B$42-X63)/B$5) -> 971.84217 | G63: =1/(1 + AW63/B$18) -> 0.94596156 | H63: =H62+B$3*I62 -> 15485.743 | I63: =(R63-H63)/B$32 -> 974.95277 | J63: =(S63-U63)/B$57 -> 0.0563911 | K63: =K62+B$3*(L62-M62) -> 0.10663772 | L63: =B$15 * (Q63 + AN63) * (1 - K63) -> 0.02442443 | M63: =K63*B$14 -> 0.0012003505 | N63: =B$16 + B$17*U63 -> 0.51414469 | O63: =AA63 -> 0.33985005 | P63: =B$21*AB63 -> 1.288083 | Q63: =P63/(B$22+P63) -> 0.4504633 | R63: =MAX(0,AL63*B$33) -> 15973.938 | S63: =B$56 + B$58 * MIN(1, MAX(0, AL63)/B$46) -> 0.79972799 | T63: =MIN(1,B$23+B$24*Z63) -> 0.20849079 | U63: =U62+B$3*J62 -> 0.51777247 | V63: =MIN(1, H63/(B$13 + H63)) -> 0.95109424 | W63: =MAX(B$8*$B$7, $B$7*(1 - $B$34*LN(1 + Y63))) + AO63 -> 197.06484 | X63: =X62+B$3*(F62-AS62) -> 727.18824 | Y63: =X63/B$28 -> 80.241887 | Z63: =Z62+B$3*(AQ62-AR62) -> 0.010731451 | AA63: =AA62+B$3*(AE62-AC62) -> 0.33985005 | AB63: =X63*B$19 -> 1528.0686 | AC63: =AA63*B$39 -> 0.0052494707 | AD63: =MIN(1,AA63^B$41) -> 0.088912661 | AE63: =B$40*P63*(1-AA63) -> 0.010162454 | AF63: =B$43*T63 -> 0.2062441 | AG63: =AG62+(AH62+AI62-AK62)*B$3 -> 278.11242 | AH63: =AG63*B$44 -> 164.91299 | AI63: =B$35*MIN(B$37*B$9,MAX(B$38*B$9,AJ63)) -> 152.28493 | AJ63: =W63*B$20/(B$20-1) -> 302.77998 | AK63: =B$45*AG63 -> 329.4405 | AL63: =AT63-AU63*W63 -> 10677830 | AM63: =B$47+B$50*MAX(0, AL63 )+B$49 *AF63 -> 373569.4 | AN63: =AM63/(B$48+AM63) -> 0.9997981 | AO63: =B$36*AP63 -> 33.077166 | AP63: =$B$10*(1 + $B$51*LN(1 + AX63/$B$12)) -> 122.65651 | AQ63: =B$54*K63*(1-Z63) -> 0.0027359851 | AR63: =Z63*B$52 -> 0.0001648494 | AS63: =X63/B$6 -> 814.40867 | AT63: =AU63*AG63 -> 36640667 | AU63: =F63*B$59*O63 -> 131747.68 | AV63: =AV62+AU62*B$3 -> 308478.51 | AW63: =B$11*(AG63/B$9)*(1 - B$55*MIN(1,V63)) -> 60.425085 | AX63: =AU63*B$61*(1-Z63) -> 129566.88 | AY63: =AY62+AL63*B$3 -> 34554318 | AZ63: =AU63*B$61 -> 130972.4 | BA63: =AZ63*Z63 -> 1405.5239 | BB63: =AX63*B$60+BA63*B$53 -> 260111.07 | BC63: =BC62+BB62*B$3 -> 610230.5
E64: =E63+B$3 -> 2003.8125 | F64: =B$4*AD64*G64*(B$9/AG64)^B$20*((B$42-X64)/B$5) -> 981.02186 | G64: =1/(1 + AW64/B$18) -> 0.94611108 | H64: =H63+B$3*I63 -> 15546.677 | I64: =(R64-H64)/B$32 -> 980.37733 | J64: =(S64-U64)/B$57 -> 0.055686211 | K64: =K63+B$3*(L63-M63) -> 0.10808922 | L64: =B$15 * (Q64 + AN64) * (1 - K64) -> 0.024440738 | M64: =K64*B$14 -> 0.0012166892 | N64: =B$16 + B$17*U64 -> 0.51696375 | O64: =AA64 -> 0.34015711 | P64: =B$21*AB64 -> 1.3055121 | Q64: =P64/(B$22+P64) -> 0.45379255 | R64: =MAX(0,AL64*B$33) -> 16037.589 | S64: =B$56 + B$58 * MIN(1, MAX(0, AL64)/B$46) -> 0.79972799 | T64: =MIN(1,B$23+B$24*Z64) -> 0.20861937 | U64: =U63+B$3*J63 -> 0.52129691 | V64: =MIN(1, H64/(B$13 + H64)) -> 0.95127658 | W64: =MAX(B$8*$B$7, $B$7*(1 - $B$34*LN(1 + Y64))) + AO64 -> 196.81091 | X64: =X63+B$3*(F63-AS63) -> 737.02783 | Y64: =X64/B$28 -> 81.327641 | Z64: =Z63+B$3*(AQ63-AR63) -> 0.010892147 | AA64: =AA63+B$3*(AE63-AC63) -> 0.34015711 | AB64: =X64*B$19 -> 1548.745 | AC64: =AA64*B$39 -> 0.0052542137 | AD64: =MIN(1,AA64^B$41) -> 0.089092903 | AE64: =B$40*P64*(1-AA64) -> 0.010295171 | AF64: =B$43*T64 -> 0.20637129 | AG64: =AG63+(AH63+AI63-AK63)*B$3 -> 277.34726 | AH64: =AG64*B$44 -> 164.45927 | AI64: =B$35*MIN(B$37*B$9,MAX(B$38*B$9,AJ64)) -> 152.28493 | AJ64: =W64*B$20/(B$20-1) -> 302.38982 | AK64: =B$45*AG64 -> 328.53412 | AL64: =AT64-AU64*W64 -> 10720378 | AM64: =B$47+B$50*MAX(0, AL64 )+B$49 *AF64 -> 375057.9 | AN64: =AM64/(B$48+AM64) -> 0.9997989 | AO64: =B$36*AP64 -> 33.089638 | AP64: =$B$10*(1 + $B$51*LN(1 + AX64/$B$12)) -> 122.70276 | AQ64: =B$54*K64*(1-Z64) -> 0.0027727757 | AR64: =Z64*B$52 -> 0.0001673179 | AS64: =X64/B$6 -> 825.42844 | AT64: =AU64*AG64 -> 36918328 | AU64: =F64*B$59*O64 -> 133112.29 | AV64: =AV63+AU63*B$3 -> 316712.74 | AW64: =B$11*(AG64/B$9)*(1 - B$55*MIN(1,V64)) -> 60.248372 | AX64: =AU64*B$61*(1-Z64) -> 130887.63 | AY64: =AY63+AL64*B$3 -> 35224342 | AZ64: =AU64*B$61 -> 132328.98 | BA64: =AZ64*Z64 -> 1441.3466 | BB64: =AX64*B$60+BA64*B$53 -> 262777.14 | BC64: =BC63+BB63*B$3 -> 626487.45
E65: =E64+B$3 -> 2003.875 | F65: =B$4*AD65*G65*(B$9/AG65)^B$20*((B$42-X65)/B$5) -> 990.07198 | G65: =1/(1 + AW65/B$18) -> 0.94625538 | H65: =H64+B$3*I64 -> 15607.951 | I65: =(R65-H65)/B$32 -> 986.8764 | J65: =(S65-U65)/B$57 -> 0.054990133 | K65: =K64+B$3*(L64-M64) -> 0.10954073 | L65: =B$15 * (Q65 + AN65) * (1 - K65) -> 0.024455549 | M65: =K65*B$14 -> 0.0012330278 | N65: =B$16 + B$17*U65 -> 0.51974757 | O65: =AA65 -> 0.34047217 | P65: =B$21*AB65 -> 1.3227374 | Q65: =P65/(B$22+P65) -> 0.4570435 | R65: =MAX(0,AL65*B$33) -> 16102.117 | S65: =B$56 + B$58 * MIN(1, MAX(0, AL65)/B$46) -> 0.79972799 | T65: =MIN(1,B$23+B$24*Z65) -> 0.20874967 | U65: =U64+B$3*J64 -> 0.5247773 | V65: =MIN(1, H65/(B$13 + H65)) -> 0.95145857 | W65: =MAX(B$8*$B$7, $B$7*(1 - $B$34*LN(1 + Y65))) + AO65 -> 196.56327 | X65: =X64+B$3*(F64-AS64) -> 746.75242 | Y65: =X65/B$28 -> 82.400704 | Z65: =Z64+B$3*(AQ64-AR64) -> 0.011054988 | AA65: =AA64+B$3*(AE64-AC64) -> 0.34047217 | AB65: =X65*B$19 -> 1569.1796 | AC65: =AA65*B$39 -> 0.0052590803 | AD65: =MIN(1,AA65^B$41) -> 0.089278051 | AE65: =B$40*P65*(1-AA65) -> 0.010426028 | AF65: =B$43*T65 -> 0.20650019 | AG65: =AG64+(AH64+AI64-AK64)*B$3 -> 276.61039 | AH65: =AG65*B$44 -> 164.02233 | AI65: =B$35*MIN(B$37*B$9,MAX(B$38*B$9,AJ65)) -> 152.28493 | AJ65: =W65*B$20/(B$20-1) -> 302.00935 | AK65: =B$45*AG65 -> 327.66125 | AL65: =AT65-AU65*W65 -> 10763512 | AM65: =B$47+B$50*MAX(0, AL65 )+B$49 *AF65 -> 376566.92 | AN65: =AM65/(B$48+AM65) -> 0.99979971 | AO65: =B$36*AP65 -> 33.101866 | AP65: =$B$10*(1 + $B$51*LN(1 + AX65/$B$12)) -> 122.7481 | AQ65: =B$54*K65*(1-Z65) -> 0.0028095479 | AR65: =Z65*B$52 -> 0.00016981936 | AS65: =X65/B$6 -> 836.31942 | AT65: =AU65*AG65 -> 37194334 | AU65: =F65*B$59*O65 -> 134464.71 | AV65: =AV64+AU64*B$3 -> 325032.26 | AW65: =B$11*(AG65/B$9)*(1 - B$55*MIN(1,V65)) -> 60.077881 | AX65: =AU65*B$61*(1-Z65) -> 132195.68 | AY65: =AY64+AL65*B$3 -> 35897061 | AZ65: =AU65*B$61 -> 133673.44 | BA65: =AZ65*Z65 -> 1477.7582 | BB65: =AX65*B$60+BA65*B$53 -> 265418.2 | BC65: =BC64+BB64*B$3 -> 642911.02
E66: =E65+B$3 -> 2003.9375 | F66: =B$4*AD66*G66*(B$9/AG66)^B$20*((B$42-X66)/B$5) -> 998.99526 | G66: =1/(1 + AW66/B$18) -> 0.94639466 | H66: =H65+B$3*I65 -> 15669.631 | I66: =(R66-H66)/B$32 -> 994.37655 | J66: =(S66-U66)/B$57 -> 0.054302757 | K66: =K65+B$3*(L65-M65) -> 0.11099214 | L66: =B$15 * (Q66 + AN66) * (1 - K66) -> 0.024468906 | M66: =K66*B$14 -> 0.0012493653 | N66: =B$16 + B$17*U66 -> 0.52249659 | O66: =AA66 -> 0.3407951 | P66: =B$21*AB66 -> 1.339759 | Q66: =P66/(B$22+P66) -> 0.46021819 | R66: =MAX(0,AL66*B$33) -> 16167.552 | S66: =B$56 + B$58 * MIN(1, MAX(0, AL66)/B$46) -> 0.79972799 | T66: =MIN(1,B$23+B$24*Z66) -> 0.20888168 | U66: =U65+B$3*J65 -> 0.52821419 | V66: =MIN(1, H66/(B$13 + H66)) -> 0.95164041 | W66: =MAX(B$8*$B$7, $B$7*(1 - $B$34*LN(1 + Y66))) + AO66 -> 196.32174 | X66: =X65+B$3*(F65-AS65) -> 756.36196 | Y66: =X66/B$28 -> 83.461073 | Z66: =Z65+B$3*(AQ65-AR65) -> 0.011219971 | AA66: =AA65+B$3*(AE65-AC65) -> 0.3407951 | AB66: =X66*B$19 -> 1589.3725 | AC66: =AA66*B$39 -> 0.0052640685 | AD66: =MIN(1,AA66^B$41) -> 0.089468046 | AE66: =B$40*P66*(1-AA66) -> 0.010555024 | AF66: =B$43*T66 -> 0.20663077 | AG66: =AG65+(AH65+AI65-AK65)*B$3 -> 275.90076 | AH66: =AG66*B$44 -> 163.60154 | AI66: =B$35*MIN(B$37*B$9,MAX(B$38*B$9,AJ66)) -> 152.28493 | AJ66: =W66*B$20/(B$20-1) -> 301.63824 | AK66: =B$45*AG66 -> 326.82066 | AL66: =AT66-AU66*W66 -> 10807252 | AM66: =B$47+B$50*MAX(0, AL66 )+B$49 *AF66 -> 378097.16 | AN66: =AM66/(B$48+AM66) -> 0.99980052 | AO66: =B$36*AP66 -> 33.11386 | AP66: =$B$10*(1 + $B$51*LN(1 + AX66/$B$12)) -> 122.79258 | AQ66: =B$54*K66*(1-Z66) -> 0.0028462993 | AR66: =Z66*B$52 -> 0.00017235372 | AS66: =X66/B$6 -> 847.08154 | AT66: =AU66*AG66 -> 37468783 | AU66: =F66*B$59*O66 -> 135805.29 | AV66: =AV65+AU65*B$3 -> 333436.3 | AW66: =B$11*(AG66/B$9)*(1 - B$55*MIN(1,V66)) -> 59.913372 | AX66: =AU66*B$61*(1-Z66) -> 133491.37 | AY66: =AY65+AL66*B$3 -> 36572514 | AZ66: =AU66*B$61 -> 135006.13 | BA66: =AZ66*Z66 -> 1514.7649 | BB66: =AX66*B$60+BA66*B$53 -> 268034.95 | BC66: =BC65+BB65*B$3 -> 659499.65
E67: =E66+B$3 -> 2004 | F67: =B$4*AD67*G67*(B$9/AG67)^B$20*((B$42-X67)/B$5) -> 1007.7945 | G67: =1/(1 + AW67/B$18) -> 0.94652911 | H67: =H66+B$3*I66 -> 15731.779 | I67: =(R67-H67)/B$32 -> 1002.8084 | J67: =(S67-U67)/B$57 -> 0.053623972 | K67: =K66+B$3*(L66-M66) -> 0.11244336 | L67: =B$15 * (Q67 + AN67) * (1 - K67) -> 0.024480854 | M67: =K67*B$14 -> 0.0012657008 | N67: =B$16 + B$17*U67 -> 0.52521125 | O67: =AA67 -> 0.34112579 | P67: =B$21*AB67 -> 1.356577 | Q67: =P67/(B$22+P67) -> 0.46331866 | R67: =MAX(0,AL67*B$33) -> 16233.923 | S67: =B$56 + B$58 * MIN(1, MAX(0, AL67)/B$46) -> 0.79972799 | T67: =MIN(1,B$23+B$24*Z67) -> 0.2090154 | U67: =U66+B$3*J66 -> 0.53160811 | V67: =MIN(1, H67/(B$13 + H67)) -> 0.95182225 | W67: =MAX(B$8*$B$7, $B$7*(1 - $B$34*LN(1 + Y67))) + AO67 -> 196.08612 | X67: =X66+B$3*(F66-AS66) -> 765.85656 | Y67: =X67/B$28 -> 84.508759 | Z67: =Z66+B$3*(AQ66-AR66) -> 0.011387092 | AA67: =AA66+B$3*(AE66-AC66) -> 0.34112579 | AB67: =X67*B$19 -> 1609.3239 | AC67: =AA67*B$39 -> 0.0052691764 | AD67: =MIN(1,AA67^B$41) -> 0.089662834 | AE67: =B$40*P67*(1-AA67) -> 0.01068216 | AF67: =B$43*T67 -> 0.20676305 | AG67: =AG66+(AH66+AI66-AK66)*B$3 -> 275.21738 | AH67: =AG67*B$44 -> 163.19631 | AI67: =B$35*MIN(B$37*B$9,MAX(B$38*B$9,AJ67)) -> 152.28493 | AJ67: =W67*B$20/(B$20-1) -> 301.27623 | AK67: =B$45*AG67 -> 326.01115 | AL67: =AT67-AU67*W67 -> 10851618 | AM67: =B$47+B$50*MAX(0, AL67 )+B$49 *AF67 -> 379649.27 | AN67: =AM67/(B$48+AM67) -> 0.99980134 | AO67: =B$36*AP67 -> 33.125628 | AP67: =$B$10*(1 + $B$51*LN(1 + AX67/$B$12)) -> 122.83622 | AQ67: =B$54*K67*(1-Z67) -> 0.0028830273 | AR67: =Z67*B$52 -> 0.00017492093 | AS67: =X67/B$6 -> 857.71495 | AT67: =AU67*AG67 -> 37741773 | AU67: =F67*B$59*O67 -> 137134.41 | AV67: =AV66+AU66*B$3 -> 341924.13 | AW67: =B$11*(AG67/B$9)*(1 - B$55*MIN(1,V67)) -> 59.754612 | AX67: =AU67*B$61*(1-Z67) -> 134775.06 | AY67: =AY66+AL67*B$3 -> 37250741 | AZ67: =AU67*B$61 -> 136327.43 | BA67: =AZ67*Z67 -> 1552.3731 | BB67: =AX67*B$60+BA67*B$53 -> 270628.11 | BC67: =BC66+BB66*B$3 -> 676251.84
E68: =E67+B$3 -> 2004.0625 | F68: =B$4*AD68*G68*(B$9/AG68)^B$20*((B$42-X68)/B$5) -> 1016.4726 | G68: =1/(1 + AW68/B$18) -> 0.94665891 | H68: =H67+B$3*I67 -> 15794.455 | I68: =(R68-H68)/B$32 -> 1012.1062 | J68: =(S68-U68)/B$57 -> 0.052953673 | K68: =K67+B$3*(L67-M67) -> 0.1138943 | L68: =B$15 * (Q68 + AN68) * (1 - K68) -> 0.024491433 | M68: =K68*B$14 -> 0.0012820331 | N68: =B$16 + B$17*U68 -> 0.52789197 | O68: =AA68 -> 0.3414641 | P68: =B$21*AB68 -> 1.3731919 | Q68: =P68/(B$22+P68) -> 0.46634692 | R68: =MAX(0,AL68*B$33) -> 16301.254 | S68: =B$56 + B$58 * MIN(1, MAX(0, AL68)/B$46) -> 0.79972799 | T68: =MIN(1,B$23+B$24*Z68) -> 0.20915083 | U68: =U67+B$3*J67 -> 0.53495961 | V68: =MIN(1, H68/(B$13 + H68)) -> 0.95200425 | W68: =MAX(B$8*$B$7, $B$7*(1 - $B$34*LN(1 + Y68))) + AO68 -> 195.85623 | X68: =X67+B$3*(F67-AS67) -> 775.23653 | Y68: =X68/B$28 -> 85.543796 | Z68: =Z67+B$3*(AQ67-AR67) -> 0.011556349 | AA68: =AA67+B$3*(AE67-AC67) -> 0.3414641 | AB68: =X68*B$19 -> 1629.0344 | AC68: =AA68*B$39 -> 0.0052744021 | AD68: =MIN(1,AA68^B$41) -> 0.089862357 | AE68: =B$40*P68*(1-AA68) -> 0.01080744 | AF68: =B$43*T68 -> 0.20689702 | AG68: =AG67+(AH67+AI67-AK67)*B$3 -> 274.55926 | AH68: =AG68*B$44 -> 162.80607 | AI68: =B$35*MIN(B$37*B$9,MAX(B$38*B$9,AJ68)) -> 152.28493 | AJ68: =W68*B$20/(B$20-1) -> 300.92302 | AK68: =B$45*AG68 -> 325.23157 | AL68: =AT68-AU68*W68 -> 10896626 | AM68: =B$47+B$50*MAX(0, AL68 )+B$49 *AF68 -> 381223.85 | AN68: =AM68/(B$48+AM68) -> 0.99980216 | AO68: =B$36*AP68 -> 33.137181 | AP68: =$B$10*(1 + $B$51*LN(1 + AX68/$B$12)) -> 122.87906 | AQ68: =B$54*K68*(1-Z68) -> 0.0029197294 | AR68: =Z68*B$52 -> 0.00017752094 | AS68: =X68/B$6 -> 868.21997 | AT68: =AU68*AG68 -> 38013400 | AU68: =F68*B$59*O68 -> 138452.44 | AV68: =AV67+AU67*B$3 -> 350495.03 | AW68: =B$11*(AG68/B$9)*(1 - B$55*MIN(1,V68)) -> 59.60138 | AX68: =AU68*B$61*(1-Z68) -> 136047.12 | AY68: =AY67+AL68*B$3 -> 37931780 | AZ68: =AU68*B$61 -> 137637.71 | BA68: =AZ68*Z68 -> 1590.5894 | BB68: =AX68*B$60+BA68*B$53 -> 273198.41 | BC68: =BC67+BB67*B$3 -> 693166.09
E69: =E68+B$3 -> 2004.125 | F69: =B$4*AD69*G69*(B$9/AG69)^B$20*((B$42-X69)/B$5) -> 1025.0323 | G69: =1/(1 + AW69/B$18) -> 0.94678425 | H69: =H68+B$3*I68 -> 15857.711 | I69: =(R69-H69)/B$32 -> 1022.2082 | J69: =(S69-U69)/B$57 -> 0.052291752 | K69: =K68+B$3*(L68-M68) -> 0.11534489 | L69: =B$15 * (Q69 + AN69) * (1 - K69) -> 0.024500685 | M69: =K69*B$14 -> 0.0012983614 | N69: =B$16 + B$17*U69 -> 0.53053919 | O69: =AA69 -> 0.34180992 | P69: =B$21*AB69 -> 1.3896046 | Q69: =P69/(B$22+P69) -> 0.46930495 | R69: =MAX(0,AL69*B$33) -> 16369.569 | S69: =B$56 + B$58 * MIN(1, MAX(0, AL69)/B$46) -> 0.79972799 | T69: =MIN(1,B$23+B$24*Z69) -> 0.20928797 | U69: =U68+B$3*J68 -> 0.53826921 | V69: =MIN(1, H69/(B$13 + H69)) -> 0.95218655 | W69: =MAX(B$8*$B$7, $B$7*(1 - $B$34*LN(1 + Y69))) + AO69 -> 195.63189 | X69: =X68+B$3*(F68-AS68) -> 784.50232 | Y69: =X69/B$28 -> 86.566233 | Z69: =Z68+B$3*(AQ68-AR68) -> 0.011727737 | AA69: =AA68+B$3*(AE68-AC68) -> 0.34180992 | AB69: =X69*B$19 -> 1648.5049 | AC69: =AA69*B$39 -> 0.0052797437 | AD69: =MIN(1,AA69^B$41) -> 0.09006656 | AE69: =B$40*P69*(1-AA69) -> 0.010930869 | AF69: =B$43*T69 -> 0.20703268 | AG69: =AG68+(AH68+AI68-AK68)*B$3 -> 273.92547 | AH69: =AG69*B$44 -> 162.43025 | AI69: =B$35*MIN(B$37*B$9,MAX(B$38*B$9,AJ69)) -> 152.28493 | AJ69: =W69*B$20/(B$20-1) -> 300.57833 | AK69: =B$45*AG69 -> 324.48081 | AL69: =AT69-AU69*W69 -> 10942291 | AM69: =B$47+B$50*MAX(0, AL69 )+B$49 *AF69 -> 382821.43 | AN69: =AM69/(B$48+AM69) -> 0.99980298 | AO69: =B$36*AP69 -> 33.148524 | AP69: =$B$10*(1 + $B$51*LN(1 + AX69/$B$12)) -> 122.92112 | AQ69: =B$54*K69*(1-Z69) -> 0.0029564031 | AR69: =Z69*B$52 -> 0.00018015368 | AS69: =X69/B$6 -> 878.59712 | AT69: =AU69*AG69 -> 38283757 | AU69: =F69*B$59*O69 -> 139759.76 | AV69: =AV68+AU68*B$3 -> 359148.31 | AW69: =B$11*(AG69/B$9)*(1 - B$55*MIN(1,V69)) -> 59.453462 | AX69: =AU69*B$61*(1-Z69) -> 137307.91 | AY69: =AY68+AL69*B$3 -> 38615673 | AZ69: =AU69*B$61 -> 138937.33 | BA69: =AZ69*Z69 -> 1629.4205 | BB69: =AX69*B$60+BA69*B$53 -> 275746.59 | BC69: =BC68+BB68*B$3 -> 710241
E70: =E69+B$3 -> 2004.1875 | F70: =B$4*AD70*G70*(B$9/AG70)^B$20*((B$42-X70)/B$5) -> 1033.4768 | G70: =1/(1 + AW70/B$18) -> 0.94690529 | H70: =H69+B$3*I69 -> 15921.599 | I70: =(R70-H70)/B$32 -> 1033.0557 | J70: =(S70-U70)/B$57 -> 0.051638105 | K70: =K69+B$3*(L69-M69) -> 0.11679504 | L70: =B$15 * (Q70 + AN70) * (1 - K70) -> 0.024508651 | M70: =K70*B$14 -> 0.0013146847 | N70: =B$16 + B$17*U70 -> 0.53315331 | O70: =AA70 -> 0.34216311 | P70: =B$21*AB70 -> 1.405816 | Q70: =P70/(B$22+P70) -> 0.4721947 | R70: =MAX(0,AL70*B$33) -> 16438.889 | S70: =B$56 + B$58 * MIN(1, MAX(0, AL70)/B$46) -> 0.79972799 | T70: =MIN(1,B$23+B$24*Z70) -> 0.2094268 | U70: =U69+B$3*J69 -> 0.54153745 | V70: =MIN(1, H70/(B$13 + H70)) -> 0.95236927 | W70: =MAX(B$8*$B$7, $B$7*(1 - $B$34*LN(1 + Y70))) + AO70 -> 195.41293 | X70: =X69+B$3*(F69-AS69) -> 793.65452 | Y70: =X70/B$28 -> 87.576136 | Z70: =Z69+B$3*(AQ69-AR69) -> 0.011901253 | AA70: =AA69+B$3*(AE69-AC69) -> 0.34216311 | AB70: =X70*B$19 -> 1667.7368 | AC70: =AA70*B$39 -> 0.0052851993 | AD70: =MIN(1,AA70^B$41) -> 0.090275385 | AE70: =B$40*P70*(1-AA70) -> 0.011052457 | AF70: =B$43*T70 -> 0.20717002 | AG70: =AG69+(AH69+AI69-AK69)*B$3 -> 273.31512 | AH70: =AG70*B$44 -> 162.06833 | AI70: =B$35*MIN(B$37*B$9,MAX(B$38*B$9,AJ70)) -> 152.28493 | AJ70: =W70*B$20/(B$20-1) -> 300.24191 | AK70: =B$45*AG70 -> 323.75782 | AL70: =AT70-AU70*W70 -> 10988628 | AM70: =B$47+B$50*MAX(0, AL70 )+B$49 *AF70 -> 384442.51 | AN70: =AM70/(B$48+AM70) -> 0.99980381 | AO70: =B$36*AP70 -> 33.159668 | AP70: =$B$10*(1 + $B$51*LN(1 + AX70/$B$12)) -> 122.96245 | AQ70: =B$54*K70*(1-Z70) -> 0.0029930462 | AR70: =Z70*B$52 -> 0.00018281912 | AS70: =X70/B$6 -> 888.84705 | AT70: =AU70*AG70 -> 38552938 | AU70: =F70*B$59*O70 -> 141056.73 | AV70: =AV69+AU69*B$3 -> 367883.3 | AW70: =B$11*(AG70/B$9)*(1 - B$55*MIN(1,V70)) -> 59.310653 | AX70: =AU70*B$61*(1-Z70) -> 138557.8 | AY70: =AY69+AL70*B$3 -> 39302462 | AZ70: =AU70*B$61 -> 140226.67 | BA70: =AZ70*Z70 -> 1668.8731 | BB70: =AX70*B$60+BA70*B$53 -> 278273.39 | BC70: =BC69+BB69*B$3 -> 727475.16
E71: =E70+B$3 -> 2004.25 | F71: =B$4*AD71*G71*(B$9/AG71)^B$20*((B$42-X71)/B$5) -> 1041.8088 | G71: =1/(1 + AW71/B$18) -> 0.94702219 | H71: =H70+B$3*I70 -> 15986.165 | I71: =(R71-H71)/B$32 -> 1044.5939 | J71: =(S71-U71)/B$57 -> 0.050992629 | K71: =K70+B$3*(L70-M70) -> 0.11824466 | L71: =B$15 * (Q71 + AN71) * (1 - K71) -> 0.02451537 | M71: =K71*B$14 -> 0.0013310022 | N71: =B$16 + B$17*U71 -> 0.53573476 | O71: =AA71 -> 0.34252356 | P71: =B$21*AB71 -> 1.4218276 | Q71: =P71/(B$22+P71) -> 0.47501809 | R71: =MAX(0,AL71*B$33) -> 16509.233 | S71: =B$56 + B$58 * MIN(1, MAX(0, AL71)/B$46) -> 0.79972799 | T71: =MIN(1,B$23+B$24*Z71) -> 0.20956734 | U71: =U70+B$3*J70 -> 0.54476483 | V71: =MIN(1, H71/(B$13 + H71)) -> 0.95255252 | W71: =MAX(B$8*$B$7, $B$7*(1 - $B$34*LN(1 + Y71))) + AO71 -> 195.19917 | X71: =X70+B$3*(F70-AS70) -> 802.69388 | Y71: =X71/B$28 -> 88.573588 | Z71: =Z70+B$3*(AQ70-AR70) -> 0.012076892 | AA71: =AA70+B$3*(AE70-AC70) -> 0.34252356 | AB71: =X71*B$19 -> 1686.7315 | AC71: =AA71*B$39 -> 0.005290767 | AD71: =MIN(1,AA71^B$41) -> 0.090488778 | AE71: =B$40*P71*(1-AA71) -> 0.011172215 | AF71: =B$43*T71 -> 0.20730904 | AG71: =AG70+(AH70+AI70-AK70)*B$3 -> 272.72733 | AH71: =AG71*B$44 -> 161.71979 | AI71: =B$35*MIN(B$37*B$9,MAX(B$38*B$9,AJ71)) -> 152.28493 | AJ71: =W71*B$20/(B$20-1) -> 299.91348 | AK71: =B$45*AG71 -> 323.06155 | AL71: =AT71-AU71*W71 -> 11035650 | AM71: =B$47+B$50*MAX(0, AL71 )+B$49 *AF71 -> 386087.52 | AN71: =AM71/(B$48+AM71) -> 0.99980465 | AO71: =B$36*AP71 -> 33.170619 | AP71: =$B$10*(1 + $B$51*LN(1 + AX71/$B$12)) -> 123.00305 | AQ71: =B$54*K71*(1-Z71) -> 0.0030296563 | AR71: =Z71*B$52 -> 0.00018551717 | AS71: =X71/B$6 -> 898.97061 | AT71: =AU71*AG71 -> 38821032 | AU71: =F71*B$59*O71 -> 142343.75 | AV71: =AV70+AU70*B$3 -> 376699.34 | AW71: =B$11*(AG71/B$9)*(1 - B$55*MIN(1,V71)) -> 59.172757 | AX71: =AU71*B$61*(1-Z71) -> 139797.17 | AY71: =AY70+AL71*B$3 -> 39992190 | AZ71: =AU71*B$61 -> 141506.12 | BA71: =AZ71*Z71 -> 1708.9541 | BB71: =AX71*B$60+BA71*B$53 -> 280779.57 | BC71: =BC70+BB70*B$3 -> 744867.24
